Workbook
Name Slicer_Category: #N/A
Name Slicer_Month: #N/A
Name Slicer_Product: #N/A
Name Slicer_Region: #N/A

Sheet Executive_Dashboard
A1: RETAIL SALES ANALYTICS DASHBOARD
A3: Business Performance Overview | January–December 2025
A4: TOTAL SALES | F4: TOTAL PROFIT | J4: TOTAL QUANTITY
A5: =KPI_Summary!B4 -> 26693247 | F5: =KPI_Summary!B5 -> 5218087.1 | J5: =KPI_Summary!B6 -> 2004
A7: TOTAL TRANSACTION | F7: AVERAGE SALES | J7: PROFIT MARGIN
A8: =KPI_Summary!B7 -> 1000 | F8: =KPI_Summary!B8 -> 26693.247 | J8: =KPI_Summary!B9 -> 0.19548342

Sheet SalesData
A1: Order_ID | B1: Order_Date | C1: Customer_ID | D1: Customer_Name | E1: Region | F1: City | G1: Product | H1: Category | I1: Quantity | J1: Unit_Price | K1: Discount | L1: Sales | M1: Cost | N1: Profit | O1: Channel | P1: Payment_Method | Q1: Customer_Segment | R1: Month | S1: Month_Number | T1: Quarter | U1: Profit_Margin
A2: 476 | B2: 45658 | C2: CUST1034 | D2: Customer 1079 | E2: East | F2: Bhubaneswar | G2: Printer | H2: Electronics | I2: 2 | J2: 8116.61 | K2: 0.1 | L2: 14609.9 | M2: 12361.71 | N2: 2248.19 | O2: Store | P2: UPI | Q2: Consumer | R2: Jan | S2: 1 | T2: Q1 | U2: 0.15388127
A3: 222 | B3: 45658 | C3: CUST1247 | D3: Customer 1128 | E3: South | F3: Hyderabad | G3: Desk | H3: Furniture | I3: 4 | J3: 4045.81 | K3: 0 | L3: 16183.24 | M3: 12790.8 | N3: 3392.44 | O3: Online | P3: Debit Card | Q3: Corporate | R3: Jan | S3: 1 | T3: Q1 | U3: 0.20962675
A4: 835 | B4: 45658 | C4: CUST1217 | D4: Customer 1034 | E4: East | F4: Patna | G4: Laptop | H4: Electronics | I4: 2 | J4: 73738.99 | K4: 0.02 | L4: 144528.42 | M4: 116899.79 | N4: 27628.63 | O4: Online | P4: Credit Card | Q4: Home Office | R4: Jan | S4: 1 | T4: Q1 | U4: 0.19116399
A5: 585 | B5: 45659 | C5: CUST1243 | D5: Customer 1297 | E5: South | F5: Chennai | G5: Water Bottle | H5: Lifestyle | I5: 1 | J5: 1122.78 | K5: 0.02 | L5: 1100.32 | M5: 767.24 | N5: 333.08 | O5: Online | P5: Debit Card | Q5: Consumer | R5: Jan | S5: 1 | T5: Q1 | U5: 0.30271194
A6: 306 | B6: 45659 | C6: CUST1022 | D6: Customer 1007 | E6: West | F6: Ahmedabad | G6: Water Bottle | H6: Lifestyle | I6: 2 | J6: 1338.35 | K6: 0.1 | L6: 2409.03 | M6: 2094.54 | N6: 314.49 | O6: Store | P6: Debit Card | Q6: Corporate | R6: Jan | S6: 1 | T6: Q1 | U6: 0.13054632
A7: 371 | B7: 45659 | C7: CUST1246 | D7: Customer 1210 | E7: East | F7: Kolkata | G7: Office Chair | H7: Furniture | I7: 2 | J7: 5083.66 | K7: 0 | L7: 10167.32 | M7: 8160.77 | N7: 2006.55 | O7: Online | P7: UPI | Q7: Corporate | R7: Jan | S7: 1 | T7: Q1 | U7: 0.19735289
A8: 554 | B8: 45661 | C8: CUST1138 | D8: Customer 1231 | E8: East | F8: Kolkata | G8: Notebook | H8: Stationery | I8: 1 | J8: 234.74 | K8: 0.15 | L8: 199.53 | M8: 178.79 | N8: 20.74 | O8: Store | P8: UPI | Q8: Corporate | R8: Jan | S8: 1 | T8: Q1 | U8: 0.10394427
A9: 36 | B9: 45661 | C9: CUST1016 | D9: Customer 1280 | E9: West | F9: Ahmedabad | G9: Backpack | H9: Lifestyle | I9: 1 | J9: 2527.24 | K9: 0 | L9: 2527.24 | M9: 1921.3 | N9: 605.94 | O9: Store | P9: Credit Card | Q9: Consumer | R9: Jan | S9: 1 | T9: Q1 | U9: 0.23976354
A10: 108 | B10: 45661 | C10: CUST1210 | D10: Customer 1161 | E10: South | F10: Hyderabad | G10: Keyboard | H10: Accessories | I10: 1 | J10: 2231.72 | K10: 0.1 | L10: 2008.55 | M10: 1715.82 | N10: 292.73 | O10: Store | P10: Net Banking | Q10: Corporate | R10: Jan | S10: 1 | T10: Q1 | U10: 0.14574195 | X10: Check | Y10: Formula
A11: 555 | B11: 45661 | C11: CUST1152 | D11: Customer 1259 | E11: East | F11: Kolkata | G11: Backpack | H11: Lifestyle | I11: 2 | J11: 919.22 | K11: 0.05 | L11: 1746.52 | M11: 1206.43 | N11: 540.09 | O11: Store | P11: UPI | Q11: Consumer | R11: Jan | S11: 1 | T11: Q1 | U11: 0.3092378 | X11: Total transaction rows | Y11: =ROWS(SalesData[Sales]) -> 1000
A12: 944 | B12: 45661 | C12: CUST1044 | D12: Customer 1056 | E12: Central | F12: Bhopal | G12: Keyboard | H12: Accessories | I12: 1 | J12: 2748.08 | K12: 0.02 | L12: 2693.12 | M12: 2304.65 | N12: 388.47 | O12: Store | P12: Cash | Q12: Corporate | R12: Jan | S12: 1 | T12: Q1 | U12: 0.14424534 | X12: Missing sales values | Y12: =COUNTBLANK(SalesData[Sales]) -> 0
A13: 396 | B13: 45661 | C13: CUST1093 | D13: Customer 1006 | E13: Central | F13: Indore | G13: Keyboard | H13: Accessories | I13: 1 | J13: 821.76 | K13: 0.15 | L13: 698.5 | M13: 601.64 | N13: 96.86 | O13: Store | P13: Credit Card | Q13: Corporate | R13: Jan | S13: 1 | T13: Q1 | U13: 0.13866858 | X13: Numeric sales values | Y13: =COUNT(SalesData[Sales]) -> 1000
A14: 253 | B14: 45662 | C14: CUST1184 | D14: Customer 1020 | E14: Central | F14: Indore | G14: Notebook | H14: Stationery | I14: 3 | J14: 92.15 | K14: 0.05 | L14: 262.63 | M14: 210.88 | N14: 51.75 | O14: Online | P14: Credit Card | Q14: Corporate | R14: Jan | S14: 1 | T14: Q1 | U14: 0.19704527 | X14: Minimum sales | Y14: =MIN(SalesData[Sales]) -> 68.37
A15: 559 | B15: 45662 | C15: CUST1218 | D15: Customer 1011 | E15: South | F15: Bengaluru | G15: Printer | H15: Electronics | I15: 2 | J15: 18028.77 | K15: 0.05 | L15: 34254.66 | M15: 26803.48 | N15: 7451.18 | O15: Store | P15: Net Banking | Q15: Corporate | R15: Jan | S15: 1 | T15: Q1 | U15: 0.2175231 | X15: Maximum sales | Y15: =MAX(SalesData[Sales]) -> 294246.68
A16: 791 | B16: 45662 | C16: CUST1250 | D16: Customer 1163 | E16: East | F16: Kolkata | G16: Office Chair | H16: Furniture | I16: 2 | J16: 11550.55 | K16: 0 | L16: 23101.1 | M16: 16115.85 | N16: 6985.25 | O16: Online | P16: Credit Card | Q16: Home Office | R16: Jan | S16: 1 | T16: Q1 | U16: 0.30237738 | X16: Negative profit records | Y16: =COUNTIF(SalesData[Profit],"<0") -> 18
A17: 114 | B17: 45662 | C17: CUST1261 | D17: Customer 1054 | E17: South | F17: Bengaluru | G17: Backpack | H17: Lifestyle | I17: 1 | J17: 995.5 | K17: 0.05 | L17: 945.72 | M17: 831.06 | N17: 114.66 | O17: Online | P17: UPI | Q17: Consumer | R17: Jan | S17: 1 | T17: Q1 | U17: 0.12124096 | X17: Zero or negative quantities | Y17: =COUNTIF(SalesData[Quantity],"<=0") -> 0
A18: 76 | B18: 45662 | C18: CUST1078 | D18: Customer 1062 | E18: East | F18: Kolkata | G18: Keyboard | H18: Accessories | I18: 3 | J18: 1344.39 | K18: 0.05 | L18: 3831.51 | M18: 2672.82 | N18: 1158.69 | O18: Store | P18: UPI | Q18: Consumer | R18: Jan | S18: 1 | T18: Q1 | U18: 0.3024108
A19: 893 | B19: 45663 | C19: CUST1144 | D19: Customer 1261 | E19: Central | F19: Indore | G19: Office Chair | H19: Furniture | I19: 3 | J19: 11375.8 | K19: 0.1 | L19: 30714.66 | M19: 25908.35 | N19: 4806.31 | O19: Online | P19: Cash | Q19: Home Office | R19: Jan | S19: 1 | T19: Q1 | U19: 0.1564826
A20: 449 | B20: 45663 | C20: CUST1280 | D20: Customer 1094 | E20: North | F20: Delhi | G20: Monitor | H20: Electronics | I20: 1 | J20: 12718.73 | K20: 0.05 | L20: 12082.79 | M20: 11086.01 | N20: 996.78 | O20: Online | P20: Net Banking | Q20: Consumer | R20: Jan | S20: 1 | T20: Q1 | U20: 0.082495847
A21: 954 | B21: 45664 | C21: CUST1200 | D21: Customer 1067 | E21: East | F21: Kolkata | G21: Office Chair | H21: Furniture | I21: 4 | J21: 14295.99 | K21: 0.02 | L21: 56040.28 | M21: 36153.42 | N21: 19886.86 | O21: Online | P21: Credit Card | Q21: Corporate | R21: Jan | S21: 1 | T21: Q1 | U21: 0.35486725
A22: 468 | B22: 45664 | C22: CUST1030 | D22: Customer 1144 | E22: North | F22: Lucknow | G22: Headphones | H22: Electronics | I22: 1 | J22: 6953.64 | K22: 0.05 | L22: 6605.96 | M22: 6040.18 | N22: 565.78 | O22: Online | P22: Debit Card | Q22: Corporate | R22: Jan | S22: 1 | T22: Q1 | U22: 0.085646901
A23: 315 | B23: 45664 | C23: CUST1137 | D23: Customer 1164 | E23: West | F23: Pune | G23: Printer | H23: Electronics | I23: 1 | J23: 6807.82 | K23: 0 | L23: 6807.82 | M23: 4903.4 | N23: 1904.42 | O23: Online | P23: UPI | Q23: Corporate | R23: Jan | S23: 1 | T23: Q1 | U23: 0.27974006 | X23: {=_xlfn._xlws.FILTER(SalesData[],SalesData[Sales]=MAX(SalesData[Sales]),"Not found")} -> 189 | Y23: 45972 | Z23: CUST1124 | AA23: Customer 1114 | AB23: East | AC23: Bhubaneswar | AD23: Laptop | AE23: Electronics | AF23: 4 | AG23: 73561.67 | AH23: 0 | AI23: 294246.68 | AJ23: 210905.26 | AK23: 83341.42 | AL23: Store | AM23: Cash | AN23: Corporate | AO23: Nov | AP23: 11 | AQ23: Q4 | AR23: 0.28323657
A24: 696 | B24: 45665 | C24: CUST1046 | D24: Customer 1114 | E24: South | F24: Chennai | G24: Notebook | H24: Stationery | I24: 1 | J24: 387.9 | K24: 0.15 | L24: 329.71 | M24: 279.59 | N24: 50.12 | O24: Online | P24: Debit Card | Q24: Home Office | R24: Jan | S24: 1 | T24: Q1 | U24: 0.15201237
A25: 237 | B25: 45665 | C25: CUST1153 | D25: Customer 1174 | E25: Central | F25: Nagpur | G25: Laptop | H25: Electronics | I25: 4 | J25: 71475.81 | K25: 0.1 | L25: 257312.92 | M25: 238303.65 | N25: 19009.27 | O25: Online | P25: Net Banking | Q25: Home Office | R25: Jan | S25: 1 | T25: Q1 | U25: 0.073876081
A26: 129 | B26: 45665 | C26: CUST1079 | D26: Customer 1027 | E26: West | F26: Ahmedabad | G26: Desk | H26: Furniture | I26: 1 | J26: 5910.95 | K26: 0 | L26: 5910.95 | M26: 3804.89 | N26: 2106.06 | O26: Store | P26: Credit Card | Q26: Home Office | R26: Jan | S26: 1 | T26: Q1 | U26: 0.35629806
A27: 51 | B27: 45665 | C27: CUST1122 | D27: Customer 1164 | E27: East | F27: Patna | G27: Printer | H27: Electronics | I27: 1 | J27: 20644.07 | K27: 0.1 | L27: 18579.66 | M27: 13372.33 | N27: 5207.33 | O27: Store | P27: Credit Card | Q27: Corporate | R27: Jan | S27: 1 | T27: Q1 | U27: 0.28027047 | X27: {=_xlfn._xlws.FILTER(SalesData[],SalesData[Profit]<0,"No loss-making transactions")} -> 786 | Y27: 45695 | Z27: CUST1048 | AA27: Customer 1183 | AB27: West | AC27: Ahmedabad | AD27: Laptop | AE27: Electronics | AF27: 3 | AG27: 55106.98 | AH27: 0.15 | AI27: 140522.8 | AJ27: 142402.05 | AK27: -1879.25 | AL27: Online | AM27: UPI | AN27: Home Office | AO27: Feb | AP27: 2 | AQ27: Q1 | AR27: -0.013373275
A28: 993 | B28: 45665 | C28: CUST1183 | D28: Customer 1134 | E28: East | F28: Patna | G28: Printer | H28: Electronics | I28: 1 | J28: 21533.67 | K28: 0.02 | L28: 21103 | M28: 15340.7 | N28: 5762.3 | O28: Online | P28: Cash | Q28: Home Office | R28: Jan | S28: 1 | T28: Q1 | U28: 0.27305596 | X28: 62 | Y28: 45718 | Z28: CUST1122 | AA28: Customer 1051 | AB28: West | AC28: Mumbai | AD28: Headphones | AE28: Electronics | AF28: 1 | AG28: 7145.36 | AH28: 0.15 | AI28: 6073.56 | AJ28: 6237.96 | AK28: -164.4 | AL28: Online | AM28: Net Banking | AN28: Consumer | AO28: Mar | AP28: 3 | AQ28: Q1 | AR28: -0.027068145
A29: 463 | B29: 45665 | C29: CUST1067 | D29: Customer 1191 | E29: South | F29: Bengaluru | G29: Monitor | H29: Electronics | I29: 1 | J29: 29935.94 | K29: 0.15 | L29: 25445.55 | M29: 20795.82 | N29: 4649.73 | O29: Store | P29: UPI | Q29: Corporate | R29: Jan | S29: 1 | T29: Q1 | U29: 0.18273254 | X29: 454 | Y29: 45722 | Z29: CUST1134 | AA29: Customer 1151 | AB29: West | AC29: Ahmedabad | AD29: Office Chair | AE29: Furniture | AF29: 1 | AG29: 12433.26 | AH29: 0.15 | AI29: 10568.27 | AJ29: 10913.9 | AK29: -345.63 | AL29: Online | AM29: Debit Card | AN29: Home Office | AO29: Mar | AP29: 3 | AQ29: Q1 | AR29: -0.032704501
A30: 976 | B30: 45666 | C30: CUST1196 | D30: Customer 1295 | E30: Central | F30: Indore | G30: Backpack | H30: Lifestyle | I30: 1 | J30: 1067.45 | K30: 0.05 | L30: 1014.08 | M30: 772.42 | N30: 241.66 | O30: Store | P30: Net Banking | Q30: Corporate | R30: Jan | S30: 1 | T30: Q1 | U30: 0.23830467 | X30: 843 | Y30: 45742 | Z30: CUST1020 | AA30: Customer 1050 | AB30: East | AC30: Kolkata | AD30: Notebook | AE30: Stationery | AF30: 1 | AG30: 369.06 | AH30: 0.15 | AI30: 313.7 | AJ30: 314.94 | AK30: -1.24 | AL30: Store | AM30: Cash | AN30: Consumer | AO30: Mar | AP30: 3 | AQ30: Q1 | AR30: -0.0039528212
A31: 300 | B31: 45667 | C31: CUST1214 | D31: Customer 1273 | E31: South | F31: Chennai | G31: Water Bottle | H31: Lifestyle | I31: 3 | J31: 622.82 | K31: 0 | L31: 1868.46 | M31: 1289.05 | N31: 579.41 | O31: Store | P31: Cash | Q31: Home Office | R31: Jan | S31: 1 | T31: Q1 | U31: 0.3101003 | X31: 678 | Y31: 45745 | Z31: CUST1278 | AA31: Customer 1082 | AB31: South | AC31: Bengaluru | AD31: Headphones | AE31: Electronics | AF31: 2 | AG31: 3557.69 | AH31: 0.15 | AI31: 6048.07 | AJ31: 6064.53 | AK31: -16.46 | AL31: Online | AM31: UPI | AN31: Corporate | AO31: Mar | AP31: 3 | AQ31: Q1 | AR31: -0.0027215293
A32: 736 | B32: 45667 | C32: CUST1187 | D32: Customer 1031 | E32: West | F32: Mumbai | G32: Desk | H32: Furniture | I32: 1 | J32: 9080.3 | K32: 0.15 | L32: 7718.25 | M32: 7435.02 | N32: 283.23 | O32: Store | P32: Cash | Q32: Consumer | R32: Jan | S32: 1 | T32: Q1 | U32: 0.036696142 | X32: 804 | Y32: 45754 | Z32: CUST1055 | AA32: Customer 1127 | AB32: East | AC32: Patna | AD32: Mouse | AE32: Accessories | AF32: 4 | AG32: 1333.77 | AH32: 0.15 | AI32: 4534.82 | AJ32: 4535.25 | AK32: -0.43 | AL32: Store | AM32: UPI | AN32: Home Office | AO32: Apr | AP32: 4 | AQ32: Q2 | AR32: -9.4821845e-05
A33: 690 | B33: 45667 | C33: CUST1106 | D33: Customer 1167 | E33: West | F33: Ahmedabad | G33: Desk | H33: Furniture | I33: 2 | J33: 5883.01 | K33: 0.15 | L33: 10001.12 | M33: 8251.57 | N33: 1749.55 | O33: Store | P33: UPI | Q33: Home Office | R33: Jan | S33: 1 | T33: Q1 | U33: 0.17493541 | X33: 569 | Y33: 45771 | Z33: CUST1076 | AA33: Customer 1164 | AB33: Central | AC33: Nagpur | AD33: Smartphone | AE33: Electronics | AF33: 3 | AG33: 35154.02 | AH33: 0.15 | AI33: 89642.75 | AJ33: 91350.06 | AK33: -1707.31 | AL33: Store | AM33: Net Banking | AN33: Consumer | AO33: Apr | AP33: 4 | AQ33: Q2 | AR33: -0.019045712
A34: 469 | B34: 45667 | C34: CUST1034 | D34: Customer 1036 | E34: West | F34: Ahmedabad | G34: Backpack | H34: Lifestyle | I34: 2 | J34: 2319.4 | K34: 0.15 | L34: 3942.98 | M34: 3926.94 | N34: 16.04 | O34: Online | P34: Credit Card | Q34: Home Office | R34: Jan | S34: 1 | T34: Q1 | U34: 0.0040679892 | X34: 42 | Y34: 45834 | Z34: CUST1100 | AA34: Customer 1233 | AB34: North | AC34: Delhi | AD34: Monitor | AE34: Electronics | AF34: 3 | AG34: 26355.61 | AH34: 0.15 | AI34: 67206.81 | AJ34: 67431.04 | AK34: -224.23 | AL34: Online | AM34: Cash | AN34: Consumer | AO34: Jun | AP34: 6 | AQ34: Q2 | AR34: -0.0033364178
A35: 73 | B35: 45667 | C35: CUST1261 | D35: Customer 1138 | E35: East | F35: Patna | G35: Monitor | H35: Electronics | I35: 1 | J35: 15733.49 | K35: 0 | L35: 15733.49 | M35: 11265.18 | N35: 4468.31 | O35: Store | P35: Credit Card | Q35: Consumer | R35: Jan | S35: 1 | T35: Q1 | U35: 0.28399993 | X35: 465 | Y35: 45863 | Z35: CUST1179 | AA35: Customer 1197 | AB35: West | AC35: Ahmedabad | AD35: Smartphone | AE35: Electronics | AF35: 2 | AG35: 43177.74 | AH35: 0.15 | AI35: 73402.16 | AJ35: 74523.17 | AK35: -1121.01 | AL35: Online | AM35: UPI | AN35: Home Office | AO35: Jul | AP35: 7 | AQ35: Q3 | AR35: -0.015272166
A36: 362 | B36: 45668 | C36: CUST1096 | D36: Customer 1190 | E36: West | F36: Ahmedabad | G36: Smartphone | H36: Electronics | I36: 4 | J36: 30677.87 | K36: 0.02 | L36: 120257.25 | M36: 102540.38 | N36: 17716.87 | O36: Online | P36: Credit Card | Q36: Corporate | R36: Jan | S36: 1 | T36: Q1 | U36: 0.14732476 | X36: 366 | Y36: 45886 | Z36: CUST1077 | AA36: Customer 1188 | AB36: West | AC36: Ahmedabad | AD36: Printer | AE36: Electronics | AF36: 2 | AG36: 14221.61 | AH36: 0.15 | AI36: 24176.74 | AJ36: 24670.96 | AK36: -494.22 | AL36: Store | AM36: Cash | AN36: Home Office | AO36: Aug | AP36: 8 | AQ36: Q3 | AR36: -0.020441962
A37: 447 | B37: 45669 | C37: CUST1188 | D37: Customer 1154 | E37: West | F37: Mumbai | G37: Backpack | H37: Lifestyle | I37: 3 | J37: 3359.52 | K37: 0 | L37: 10078.56 | M37: 6450.97 | N37: 3627.59 | O37: Store | P37: UPI | Q37: Consumer | R37: Jan | S37: 1 | T37: Q1 | U37: 0.35993138 | X37: 286 | Y37: 45904 | Z37: CUST1008 | AA37: Customer 1141 | AB37: Central | AC37: Indore | AD37: Smartphone | AE37: Electronics | AF37: 1 | AG37: 43837.51 | AH37: 0.15 | AI37: 37261.88 | AJ37: 38040.14 | AK37: -778.26 | AL37: Store | AM37: Cash | AN37: Home Office | AO37: Sep | AP37: 9 | AQ37: Q3 | AR37: -0.020886225
A38: 914 | B38: 45669 | C38: CUST1078 | D38: Customer 1172 | E38: East | F38: Kolkata | G38: Printer | H38: Electronics | I38: 1 | J38: 18378.36 | K38: 0.05 | L38: 17459.44 | M38: 14318.49 | N38: 3140.95 | O38: Store | P38: Credit Card | Q38: Consumer | R38: Jan | S38: 1 | T38: Q1 | U38: 0.17989981 | X38: 638 | Y38: 45915 | Z38: CUST1204 | AA38: Customer 1262 | AB38: North | AC38: Jaipur | AD38: Headphones | AE38: Electronics | AF38: 1 | AG38: 6990.45 | AH38: 0.15 | AI38: 5941.88 | AJ38: 6105.72 | AK38: -163.84 | AL38: Online | AM38: Debit Card | AN38: Consumer | AO38: Sep | AP38: 9 | AQ38: Q3 | AR38: -0.027573765
A39: 495 | B39: 45670 | C39: CUST1271 | D39: Customer 1089 | E39: East | F39: Kolkata | G39: Water Bottle | H39: Lifestyle | I39: 1 | J39: 1261.13 | K39: 0.1 | L39: 1135.02 | M39: 951.52 | N39: 183.5 | O39: Online | P39: Cash | Q39: Corporate | R39: Jan | S39: 1 | T39: Q1 | U39: 0.16167116 | X39: 507 | Y39: 45935 | Z39: CUST1018 | AA39: Customer 1012 | AB39: East | AC39: Bhubaneswar | AD39: Notebook | AE39: Stationery | AF39: 3 | AG39: 287.51 | AH39: 0.15 | AI39: 733.15 | AJ39: 736.02 | AK39: -2.87 | AL39: Store | AM39: Debit Card | AN39: Corporate | AO39: Oct | AP39: 10 | AQ39: Q4 | AR39: -0.003914615
... A44: 446 | B44: 45672 | C44: CUST1102 | D44: Customer 1226 | E44: Central | F44: Indore | G44: Printer | H44: Electronics | I44: 2 | J44: 14925.98 | K44: 0.15 | L44: 25374.17 | M44: 18886.16 | N44: 6488.01 | O44: Online | P44: UPI | Q44: Consumer | R44: Jan | S44: 1 | T44: Q1 | U44: 0.25569349 | X44: 441 | Y44: 46021 | Z44: CUST1095 | AA44: Customer 1011 | AB44: South | AC44: Hyderabad | AD44: Office Chair | AE44: Furniture | AF44: 2 | AG44: 16731.24 | AH44: 0.15 | AI44: 28443.11 | AJ44: 28625.15 | AK44: -182.04 | AL44: Store | AM44: Debit Card | AN44: Corporate | AO44: Dec | AP44: 12 | AQ44: Q4 | AR44: -0.006400144
...

Sheet Data_Quality_Summary
A1: Data Quality Summary | B1: Retail Sales Analytics
A2: Dataset | B2: Retail Sales Data (2025)
A3: Total Transactions | B3: 1000
A5: Check | B5: Result | C5: Status | D5: Notes
A6: Transaction Count | B6: 1000 | C6: Passed | D6: Expected dataset size
A7: Missing Sales Values | B7: 0 | C7: Passed | D7: No missing Sales values
A8: Numeric Sales Values | B8: 1000 | C8: Passed | D8: All Sales values are numeric
A9: Exact Duplicate Rows | B9: 0 | C9: Passed | D9: No exact duplicate rows found
A10: Minimum Sales | B10: 68.37 | C10: Reviewed | D10: Minimum observed Sales value
A11: Maximum Sales | B11: 294246.68 | C11: Reviewed | D11: Maximum value inspected and considered reasonable
A12: Negative Profit Records | B12: 18 | C12: Reviewed | D12: Loss-making transactions retained
A13: Zero or Negative Quantities | B13: 0 | C13: Passed | D13: No zero or negative quantities found
A14: Date and Numeric Formats | B14: Visually checked | C14: Reviewed | D14: Formats appear correct on initial inspection

Sheet KPI_Summary
A1: Retail Sales Analytics — KPI Summary.
A3: KPI | B3: Value | C3: Business Meaning
A4: Total Sales Sum of all sales revenue. | B4: =SUM(SalesData[Sales]) -> 26693247
A5: Total Profit Total profit across transactions. | B5: =SUM(SalesData[Profit]) -> 5218087.1
A6: Total Quantity Total units sold. | B6: =SUM(SalesData[Quantity]) -> 2004
A7: Total Transactions Number of data rows. | B7: =COUNTA(SalesData[Order_ID]) -> 1000
A8: Average Sales per Transaction Average revenue per data row. | B8: =AVERAGE(SalesData[Sales]) -> 26693.247
A9: Profit Margin Profit as a percentage of sales. | B9: =IFERROR(B5/B4,0) -> 0.19548342

Sheet Region_Analysis
A3: Row Labels | B3: Sum of Sales | C3: Sum of Profit | E3: Profit Margin
A4: South | B4: 5911021.3 | C4: 1210050.4 | E4: =C4/B4 -> 0.20471089
A5: Grand Total | B5: 5911021.3 | C5: 1210050.4 | E5: =C5/B5 -> 0.20471089
E6: =C6/B6 -> #DIV/0!
E7: =C7/B7 -> #DIV/0!
E8: =C8/B8 -> #DIV/0!
E9: =C9/B9 -> #DIV/0!

Sheet Category_Analysis
A3: Row Labels | B3: Sum of Sales | C3: Sum of Profit | D3: Profit Margin
A4: Accessories | B4: 129783.9 | C4: 23507.68 | D4: =C4/B4 -> 0.1811294
A5: Electronics | B5: 5040127.5 | C5: 1042142.5 | D5: =C5/B5 -> 0.20676908
A6: Furniture | B6: 664200.32 | C6: 128686.31 | D6: =C6/B6 -> 0.19374623
A7: Lifestyle | B7: 67693 | C7: 13790.86 | D7: =C7/B7 -> 0.20372653
A8: Stationery | B8: 9216.53 | C8: 1923.03 | D8: =C8/B8 -> 0.20865011
A9: Grand Total | B9: 5911021.3 | C9: 1210050.4 | D9: =C9/B9 -> 0.20471089
A14: Highest sales and profit: Electronics Highest profit margin: Lifestyle (20.30%) Lowest sales and profit: Stationery Overall profit margin: 19.55%

Sheet Product_Analysis
A3: Row Labels | B3: Sum of Sales | C3: Sum of Profit | D3: Sum of Quantity | G3: Which product generates the highest sales? =Laptop Which product generates the highest profit? =Laptop Which product has the highest quantity sold? =Office Chair — 196 Which product has the lowest sales? =Notebook Which product has the lowest profit? =Notebook
A4: Laptop | B4: 2121743.2 | C4: 464492.56 | D4: 34
A5: Smartphone | B5: 1746782 | C5: 312036.87 | D5: 53
A6: Monitor | B6: 619819.26 | C6: 144136.65 | D6: 34
A7: Printer | B7: 402628.79 | C7: 90333.57 | D7: 34
A8: Office Chair | B8: 381631.66 | C8: 66320.63 | D8: 36
A9: Desk | B9: 282568.66 | C9: 62365.68 | D9: 34
A10: Headphones | B10: 149154.31 | C10: 31142.89 | D10: 37
A11: Keyboard | B11: 85867.93 | C11: 13721.04 | D11: 39
A12: Backpack | B12: 45706.62 | C12: 8788.65 | D12: 25
A13: Mouse | B13: 43915.97 | C13: 9786.64 | D13: 33
A14: Water Bottle | B14: 21986.38 | C14: 5002.21 | D14: 30
A15: Notebook | B15: 9216.53 | C15: 1923.03 | D15: 36
A16: Grand Total | B16: 5911021.3 | C16: 1210050.4 | D16: 425
A21: Row Labels | B21: Sum of Sales
A22: Laptop | B22: 42707.39
A23: Smartphone | B23: 129222.59
A24: Monitor | B24: 222435.21
A25: Office Chair | B25: 310489.67
A26: Printer | B26: 325350.47
A27: Desk | B27: 614540.63
A28: Headphones | B28: 1501294
A29: Backpack | B29: 1941008.3
A30: Keyboard | B30: 2044131.5
A31: Mouse | B31: 2971153.5
A32: Water Bottle | B32: 6568381.3
A33: Notebook | B33: 10022533

Sheet Monthly Sales Analysis
A3: Row Labels | B3: Sum of Sales | C3: Sum of Profit | D3: Count of Order_ID
A4: Jan | B4: 364376.78 | C4: 65434.97 | D4: 20
A5: Feb | B5: 231485.3 | C5: 62472.39 | D5: 16
A6: Mar | B6: 123912.29 | C6: 14560.23 | D6: 13
A7: Apr | B7: 528408.52 | C7: 90548.52 | D7: 24
A8: May | B8: 245958.6 | C8: 57110.8 | D8: 14
A9: Jun | B9: 285393.05 | C9: 59322.47 | D9: 16
A10: Jul | B10: 632309.97 | C10: 135648.68 | D10: 19
A11: Aug | B11: 645964.29 | C11: 166400.08 | D11: 20
A12: Sep | B12: 663150.21 | C12: 138188.56 | D12: 15
A13: Oct | B13: 407123.12 | C13: 70741.28 | D13: 17
A14: Nov | B14: 600979.33 | C14: 106855.34 | D14: 14
A15: Dec | B15: 1181959.8 | C15: 242767.1 | D15: 27
A16: Grand Total | B16: 5911021.3 | C16: 1210050.4 | D16: 215
A23: November was the strongest month November generated the highest sales and profit in your dataset. March was the weakest month March had the lowest sales and profit. You can investigate this further later, but these figures alone do not explain why performance was lower.

Sheet Quarterly_Analysis
A3: Row Labels | B3: Sum of Sales | C3: Sum of Profit
A4: Qtr1 | B4: 6263604.5 | C4: 1204144.4
A5: Qtr2 | B5: 6183485.4 | C5: 1144858.4
A6: Qtr3 | B6: 6792473.1 | C6: 1343338.9
A7: Qtr4 | B7: 7453684.1 | C7: 1525745.4
A8: Grand Total | B8: 26693247 | C8: 5218087.1
A11: Best quarter: Q4 7,453,684.12 Sales · Profit: 1,525,745.40 Q4 generated the highest sales and profit, contributing approximately 27.9% of annual sales. Lowest sales: Q2 6,183,485.42 Profit: 1,144,858.41 Q2 recorded the lowest sales and profit of the four quarters. Sales improved in Q3 and Q4 Sales increased from Q2 through Q4, with Q4 outperforming all other quarters.

Sheet Channel_Analysis
A3: Row Labels | B3: Sum of Sales | C3: Sum of Profit | D3: Count of Order_ID | E3: Progit Margin | G3: Business insights Online generates more sales Online sales are approximately 13.85 million, about 1.01 million higher than Store sales. Store generates more profit Store profit is approximately 2.64 million, around 56,491 higher than Online profit. Store has the stronger profit margin Store margin is 20.53%, compared with Online at 18.63%—a difference of approximately 1.90 percentage points.
A4: Online | B4: 3311980.9 | C4: 689563.86 | D4: 104 | E4: =C4/B4 -> 0.20820285
A5: Store | B5: 2599040.4 | C5: 520486.56 | D5: 111 | E5: =C5/B5 -> 0.20026105
A6: Grand Total | B6: 5911021.3 | C6: 1210050.4 | D6: 215 | E6: =C6/B6 -> 0.20471089
A35: Row Labels | B35: Sum of Sales
A36: Online | B36: 13849942
A37: Store | B37: 12843305
A43: Row Labels | B43: Sum of Profit
A44: Online | B44: 2580797.8
A45: Store | B45: 2637289.3

Sheet Segment_Analysis
A3: Row Labels | B3: Sum of Sales | C3: Sum of Profit | D3: Count of Order_ID | E3: Profit Margin
A4: Consumer | B4: 1665210.3 | C4: 316249.21 | D4: 65 | E4: =C4/B4 -> 0.18991548
A5: Corporate | B5: 2482332.3 | C5: 492810.41 | D5: 76 | E5: =C5/B5 -> 0.19852717
A6: Home Office | B6: 1763478.6 | C6: 400990.8 | D6: 74 | E6: =C6/B6 -> 0.22738625
A7: Grand Total | B7: 5911021.3 | C7: 1210050.4 | D7: 215 | E7: =C7/B7 -> 0.20471089
A12: Consumer | B12: 7978674.4
A13: Corporate | B13: 9451379.5
A14: Home Office | B14: 9263193.2
A18: Consumer | B18: 1546479.5
A19: Corporate | B19: 1828620.8
A20: Home Office | B20: 1842986.8
E32: Highest sales: Corporate Corporate generates approximately 9.45 million in sales, the highest of the three segments. Highest profit: Home Office Home Office generates approximately 1.84 million in profit, slightly above Corporate despite having lower sales. Highest profit margin: Home Office At 19.90%, Home Office has the strongest margin. Corporate has the lowest margin at approximately 19.35%.

Sheet Payment_Analysis.
A3: Row Labels | B3: Sum of Sales | C3: Sum of Profit | D3: Count of Order_ID | E3: Profit Margin
A4: UPI | B4: 1735523.4 | C4: 333229.47 | D4: 46 | E4: =C4/B4 -> 0.19200518
A5: Credit Card | B5: 1423128.1 | C5: 279513.68 | D5: 39 | E5: =C5/B5 -> 0.19640795
A6: Debit Card | B6: 1065263.9 | C6: 204641.31 | D6: 44 | E6: =C6/B6 -> 0.19210387
A7: Net Banking | B7: 926429.51 | C7: 218861.95 | D7: 48 | E7: =C7/B7 -> 0.23624242
A8: Cash | B8: 760676.4 | C8: 173804.01 | D8: 38 | E8: =C8/B8 -> 0.22848613
A9: Grand Total | B9: 5911021.3 | C9: 1210050.4 | D9: 215 | E9: =C9/B9 -> 0.20471089
A15: Credit Card | B15: 5861819.2
A16: UPI | B16: 5618429.9
A17: Net Banking | B17: 5436298.5
A18: Debit Card | B18: 5225885
A19: Cash | B19: 4550814.6
A23: Credit Card | B23: 1183054.8
A24: UPI | B24: 1026605.1
A25: Net Banking | B25: 1034856.8
A26: Debit Card | B26: 997928.8
A27: Cash | B27: 975641.64
D33: Highest sales and profit: Credit Card Credit Card generates approximately 5.86 million in sales and 1.18 million in profit, the highest totals among the payment methods. Highest profit margin: Cash Cash has the highest margin at 21.44%, despite having the lowest sales total. Most transactions: UPI UPI records 217 transactions, the highest count, but has the lowest profit margin at 18.27%.

Sheet Business_Insights.
A1: Retail Sales Analytics — Business Insights Reporting Period: January–December 2025 Dataset: 1,000 transaction rows 1. Overall Business Performance Total Sales: ₹26,693,247.13 Total Profit: ₹5,218,087.13 Total Quantity Sold: 2,004 units Average Sales per Transaction Row: ₹26,693.25 Overall Profit Margin: 19.55% The business generated approximately ₹2.67 crore in sales and ₹52.18 lakh in profit during 2025, with an overall profit margin of 19.55%. 2. Regional Performance West generated the highest sales at approximately ₹63.54 lakh. South generated the highest profit at approximately ₹12.10 lakh. North had the lowest sales at approximately ₹45.09 lakh. Central had the lowest profit at approximately ₹8.29 lakh and the lowest regional profit margin, at 17.62%. North recorded the highest regional profit margin, at approximately 20.61%. Business implication: Investigate the factors contributing to Central's lower profitability. Study the practices, product mix and operating conditions in the better-performing regions before deciding where to invest in growth. 3. Category Performance Electronics contributed approximately 82.9% of total sales. Furniture generated approximately ₹7.12 lakh in profit. Lifestyle recorded the highest category profit margin, at approximately 20.30%. Stationery generated the lowest sales and profit among the five categories. Business implication: Protect the availability and profitability of Electronics while evaluating opportunities to grow smaller categories. Assess whether Lifestyle's higher margin can be sustained as sales increase. 4. Product Performance Laptop was the highest-selling product, generating approximately ₹1.00 crore in sales and ₹19.35 lakh in profit. Smartphone ranked second in sales, generating approximately ₹65.68 lakh. Laptop and Smartphone together contributed approximately 62.2% of total sales. Notebook recorded the lowest product sales and profit. Office Chair had the highest quantity sold, at 196 units. Business implication: Monitor stock availability for Laptop and Smartphone because of their substantial contribution to revenue. Investigate Notebook demand and profitability before making inventory or product-range decisions. 5. Monthly and Quarterly Trends November recorded the highest monthly sales, at approximately ₹26.24 lakh, and the highest monthly profit, at approximately ₹5.27 lakh. March recorded the lowest monthly sales and profit. Q4 was the strongest quarter, generating approximately ₹74.54 lakh in sales and ₹15.26 lakh in profit. Q2 was the weakest quarter by total sales and profit. Q4 contributed approximately 27.9% of annual sales. Business implication: Investigate the reasons behind the November and Q4 peaks. Plan inventory and promotional activity around demonstrated demand patterns, while examining the March and Q2 slowdown. 6. Sales Channel Performance Online sales were approximately ₹1.385 crore, higher than Store sales of approximately ₹1.284 crore. Store sales generated approximately ₹26.37 lakh in profit, compared with approximately ₹25.81 lakh for Online. Store had a higher profit margin, approximately 20.53%, compared with Online at 18.63%. Business implication: Review online discounts, fulfilment expenses and product mix to understand the lower online margin. Use the stronger store profitability as a benchmark while considering the online channel's larger sales contribution. 7. Customer Segment Performance Corporate generated the highest sales, at approximately ₹94.51 lakh. Home Office generated the highest profit, at approximately ₹18.43 lakh, and the highest segment profit margin, at approximately 19.90%. Consumer generated approximately ₹79.79 lakh in sales. Business implication: Explore opportunities to retain and grow Corporate sales while identifying the products and customer needs contributing to Home Office profitability. 8. Payment Method Performance Credit Card generated the highest sales and profit among payment methods. Cash had the highest payment-method profit margin, at approximately 21.44%. UPI recorded the highest transaction-row count, at 217, but the lowest payment-method profit margin, at approximately 18.27%. Business implication: Investigate differences in discounts, product mix and transaction values across payment methods. Do not assume that the payment method itself caused the margin differences. 9. Data Quality Observations The dataset contains 1,000 transaction rows. No missing Sales values were found. No exact duplicate rows were found. No zero or negative Quantity records were found. Eighteen records had negative Profit values and were retained for investigation. Business implication: Review negative-profit transactions to identify possible loss-making sales, discounts or other contributing factors. Negative profit is not automatically a data error. 10. Overall Recommendations Review Central's profitability and identify opportunities to improve its margin. Monitor inventory and profitability for Laptop and Smartphone. Investigate November and Q4 sales drivers and plan inventory accordingly. Examine online-channel costs and discounting to improve profitability. Evaluate low-performing products and categories before changing inventory allocation. Review negative-profit transactions and monitor margins regularly. Use the interactive Excel dashboard to compare regions, categories, channels and customer segments. Conclusion: The analysis indicates that Electronics, Laptop and Smartphone are major revenue contributors, while regional, channel and seasonal differences provide opportunities for further investigation. The recommendations should be validated with additional operational and cost data before major business decisions are made.
